Workbook

Sheet Sammanfattning
A1: Så röstade Majorna i valet 2022
A2: Klassiska stadsdelen Majorna = primärområdena Majorna (103), Stigberget (104), Kungsladugård (101), Sanna (102) — 23 valdistrikt. Slutlig rösträkning.
A4: Riksdagsvalet
A5: Parti | B5: Röster Majorna | C5: Andel Majorna | D5: Andel Göteborg | E5: Andel Riket
A6: V | B6: =RD!C25 -> 5793 | C6: =B6/$B$15 -> 0.27186972 | D6: 0.12849788 | E6: 0.067467123
A7: S | B7: =RD!D25 -> 5515 | C7: =B7/$B$15 -> 0.25882298 | D7: 0.27651734 | E7: 0.30325457
A8: MP | B8: =RD!E25 -> 3349 | C8: =B8/$B$15 -> 0.15717102 | D8: 0.079183989 | E8: 0.050824873
A9: SD | B9: =RD!F25 -> 2152 | C9: =B9/$B$15 -> 0.10099493 | D9: 0.14661066 | E9: 0.2053614
A10: M | B10: =RD!G25 -> 1894 | C10: =B10/$B$15 -> 0.088886803 | D10: 0.18483563 | E10: 0.19102095
A11: C | B11: =RD!H25 -> 910 | C11: =B11/$B$15 -> 0.042706965 | D11: 0.058607964 | E11: 0.067142176
A12: L | B12: =RD!I25 -> 886 | C12: =B12/$B$15 -> 0.041580627 | D12: 0.058533058 | E12: 0.046085734
A13: KD | B13: =RD!J25 -> 491 | C13: =B13/$B$15 -> 0.023042989 | D13: 0.043704606 | E13: 0.053367336
A14: Övriga | B14: =RD!K25 -> 318 | C14: =B14/$B$15 -> 0.014923972
A15: Giltiga röster | B15: =SUM(B6:B14) -> 21308
A16: Valdeltagande | B16: =RD!O25 -> 0.82763522 | D16: 0.8071 | E16: 0.84211866
A19: Regionvalet (Västra Götaland)
A20: Parti | B20: Röster Majorna | C20: Andel Majorna | D20: Andel Göteborg | E20: Andel Västra Götaland
A21: V | B21: =RF!C25 -> 7723 | C21: =B21/$B$32 -> 0.35804358 | D21: 0.16608497 | E21: 0.1004002
A22: S | B22: =RF!D25 -> 5519 | C22: =B22/$B$32 -> 0.25586463 | D22: 0.27913889 | E22: 0.29447562
A23: MP | B23: =RF!E25 -> 1766 | C23: =B23/$B$32 -> 0.081872972 | D23: 0.049878415 | E23: 0.03558142
A24: M | B24: =RF!F25 -> 1753 | C24: =B24/$B$32 -> 0.081270283 | D24: 0.16985839 | E24: 0.18435404
A25: SD | B25: =RF!G25 -> 1610 | C25: =B25/$B$32 -> 0.074640705 | D25: 0.1081705 | E25: 0.15425196
A26: L | B26: =RF!H25 -> 809 | C26: =B26/$B$32 -> 0.037505795 | D26: 0.052684881 | E26: 0.047772767
A27: C | B27: =RF!I25 -> 680 | C27: =B27/$B$32 -> 0.031525267 | D27: 0.044743241 | E27: 0.059433975
A28: KD | B28: =RF!J25 -> 635 | C28: =B28/$B$32 -> 0.029439036 | D28: 0.055963381 | E28: 0.079291949
A29: D | B29: =RF!K25 -> 558 | C29: =B29/$B$32 -> 0.025869263 | D29: 0.042600486 | E29: 0.021065617
A30: FI | B30: =RF!L25 -> 158 | C30: =B30/$B$32 -> 0.0073249884 | D30: 0.003292805 | E30: 0.0019769
A31: Övriga | B31: =RF!M25 -> 359 | C31: =B31/$B$32 -> 0.016643486
A32: Giltiga röster | B32: =SUM(B21:B31) -> 21570
A33: Valdeltagande | B33: =RF!Q25 -> 0.81654636 | D33: 0.7629 | E33: 0.80349204
A36: Kommunvalet (Göteborg)
A37: Parti | B37: Röster Majorna | C37: Andel Majorna | D37: Andel Göteborg
A38: V | B38: =KF!C25 -> 7479 | C38: =B38/$B$50 -> 0.34592969 | D38: 0.15820966
A39: S | B39: =KF!D25 -> 4997 | C39: =B39/$B$50 -> 0.23112858 | D39: 0.26440589
A40: MP | B40: =KF!E25 -> 2067 | C40: =B40/$B$50 -> 0.09560592 | D40: 0.059861343
A41: M | B41: =KF!F25 -> 1783 | C41: =B41/$B$50 -> 0.082469935 | D41: 0.17119164
A42: SD | B42: =KF!G25 -> 1578 | C42: =B42/$B$50 -> 0.072987974 | D42: 0.10745908
A43: L | B43: =KF!H25 -> 848 | C43: =B43/$B$50 -> 0.039222942 | D43: 0.055445646
A44: D | B44: =KF!I25 -> 844 | C44: =B44/$B$50 -> 0.039037928 | D44: 0.061389305
A45: C | B45: =KF!J25 -> 627 | C45: =B45/$B$50 -> 0.029000925 | D45: 0.040034892
...

Sheet RD
A1: Distriktskod | B1: Valdistrikt | C1: V | D1: S | E1: MP | F1: SD | G1: M | H1: C | I1: L | J1: KD | K1: Övriga | L1: Giltiga röster | M1: Röstande | N1: Röstberättigade | O1: Valdeltagande
A2: 14800526 | B2: Svalebo | C2: 179 | D2: 217 | E2: 114 | F2: 102 | G2: 60 | H2: 43 | I2: 42 | J2: 25 | K2: 15 | L2: =SUM(C2:K2) -> 797 | M2: 805 | N2: 1073 | O2: =M2/N2 -> 0.75023299
A3: 14800527 | B3: Skytteskogen | C3: 156 | D3: 228 | E3: 215 | F3: 60 | G3: 131 | H3: 76 | I3: 71 | J3: 35 | K3: 9 | L3: =SUM(C3:K3) -> 981 | M3: 986 | N3: 1115 | O3: =M3/N3 -> 0.88430493
A4: 14800528 | B4: Kungsladugård Östra | C4: 266 | D4: 221 | E4: 138 | F4: 104 | G4: 63 | H4: 35 | I4: 40 | J4: 21 | K4: 17 | L4: =SUM(C4:K4) -> 905 | M4: 915 | N4: 1112 | O4: =M4/N4 -> 0.82284173
A5: 14800529 | B5: Kungsladugård Västra | C5: 254 | D5: 219 | E5: 184 | F5: 91 | G5: 58 | H5: 34 | I5: 26 | J5: 12 | K5: 7 | L5: =SUM(C5:K5) -> 885 | M5: 896 | N5: 1087 | O5: =M5/N5 -> 0.82428703
A6: 14800530 | B6: Mariaplan | C6: 287 | D6: 199 | E6: 151 | F6: 72 | G6: 57 | H6: 16 | I6: 30 | J6: 12 | K6: 9 | L6: =SUM(C6:K6) -> 833 | M6: 842 | N6: 1014 | O6: =M6/N6 -> 0.83037475
A7: 14800531 | B7: Silverkällan | C7: 248 | D7: 224 | E7: 167 | F7: 68 | G7: 73 | H7: 44 | I7: 32 | J7: 13 | K7: 15 | L7: =SUM(C7:K7) -> 884 | M7: 893 | N7: 1048 | O7: =M7/N7 -> 0.85209924
A8: 14800532 | B8: Sannaplan | C8: 298 | D8: 259 | E8: 159 | F8: 98 | G8: 66 | H8: 33 | I8: 39 | J8: 26 | K8: 21 | L8: =SUM(C8:K8) -> 999 | M8: 1010 | N8: 1211 | O8: =M8/N8 -> 0.83402147
A9: 14800533 | B9: Sandarne | C9: 318 | D9: 315 | E9: 135 | F9: 112 | G9: 135 | H9: 55 | I9: 45 | J9: 29 | K9: 18 | L9: =SUM(C9:K9) -> 1162 | M9: 1174 | N9: 1400 | O9: =M9/N9 -> 0.83857143
A10: 14800534 | B10: Klippan | C10: 205 | D10: 207 | E10: 111 | F10: 108 | G10: 84 | H10: 43 | I10: 48 | J10: 32 | K10: 11 | L10: =SUM(C10:K10) -> 849 | M10: 855 | N10: 1035 | O10: =M10/N10 -> 0.82608696
A11: 14800535 | B11: Gröna Vallen | C11: 248 | D11: 205 | E11: 106 | F11: 92 | G11: 64 | H11: 32 | I11: 22 | J11: 8 | K11: 10 | L11: =SUM(C11:K11) -> 787 | M11: 798 | N11: 973 | O11: =M11/N11 -> 0.82014388
A12: 14800536 | B12: Kusttorget | C12: 259 | D12: 251 | E12: 81 | F12: 122 | G12: 88 | H12: 35 | I12: 37 | J12: 10 | K12: 18 | L12: =SUM(C12:K12) -> 901 | M12: 913 | N12: 1160 | O12: =M12/N12 -> 0.78706897
A13: 14800537 | B13: Chapmans Torg | C13: 177 | D13: 217 | E13: 96 | F13: 99 | G13: 103 | H13: 30 | I13: 45 | J13: 30 | K13: 14 | L13: =SUM(C13:K13) -> 811 | M13: 816 | N13: 1009 | O13: =M13/N13 -> 0.80872151
... A24: 14800548 | B24: Gatenhielmska | C24: 291 | D24: 249 | E24: 146 | F24: 102 | G24: 64 | H24: 39 | I24: 27 | J24: 24 | K24: 14 | L24: =SUM(C24:K24) -> 956 | M24: 963 | N24: 1182 | O24: =M24/N24 -> 0.81472081
B25: Majorna totalt | C25: =SUM(C2:C24) -> 5793 | D25: =SUM(D2:D24) -> 5515 | E25: =SUM(E2:E24) -> 3349 | F25: =SUM(F2:F24) -> 2152 | G25: =SUM(G2:G24) -> 1894 | H25: =SUM(H2:H24) -> 910 | I25: =SUM(I2:I24) -> 886 | J25: =SUM(J2:J24) -> 491 | ... N25: =SUM(N2:N24) -> 26032 | O25: =M25/N25 -> 0.82763522

Sheet RF
A1: Distriktskod | B1: Valdistrikt | C1: V | D1: S | E1: MP | F1: M | G1: SD | H1: L | I1: C | J1: KD | K1: D | L1: FI | M1: Övriga | N1: Giltiga röster | O1: Röstande | P1: Röstberättigade | Q1: Valdeltagande
A2: 14800526 | B2: Svalebo | C2: 260 | D2: 207 | E2: 60 | F2: 56 | G2: 81 | H2: 36 | I2: 33 | J2: 35 | K2: 19 | L2: 7 | M2: 14 | N2: =SUM(C2:M2) -> 808 | O2: 820 | P2: 1130 | Q2: =O2/P2 -> 0.72566372
A3: 14800527 | B3: Skytteskogen | C3: 258 | D3: 231 | E3: 124 | F3: 114 | G3: 45 | H3: 70 | I3: 47 | J3: 48 | K3: 46 | L3: 8 | M3: 8 | N3: =SUM(C3:M3) -> 999 | O3: 1006 | P3: 1148 | Q3: =O3/P3 -> 0.87630662
A4: 14800528 | B4: Kungsladugård Östra | C4: 348 | D4: 207 | E4: 78 | F4: 60 | G4: 75 | H4: 30 | I4: 32 | J4: 29 | K4: 19 | L4: 10 | M4: 22 | N4: =SUM(C4:M4) -> 910 | O4: 917 | P4: 1135 | Q4: =O4/P4 -> 0.80792952
A5: 14800529 | B5: Kungsladugård Västra | C5: 347 | D5: 242 | E5: 92 | F5: 53 | G5: 69 | H5: 19 | I5: 21 | J5: 18 | K5: 18 | L5: 8 | M5: 9 | N5: =SUM(C5:M5) -> 896 | O5: 908 | P5: 1115 | Q5: =O5/P5 -> 0.81434978
A6: 14800530 | B6: Mariaplan | C6: 384 | D6: 180 | E6: 75 | F6: 45 | G6: 60 | H6: 22 | I6: 17 | J6: 15 | K6: 31 | L6: 3 | M6: 9 | N6: =SUM(C6:M6) -> 841 | O6: 851 | P6: 1034 | Q6: =O6/P6 -> 0.82301741
A7: 14800531 | B7: Silverkällan | C7: 348 | D7: 226 | E7: 78 | F7: 68 | G7: 53 | H7: 24 | I7: 29 | J7: 17 | K7: 27 | L7: 6 | M7: 16 | N7: =SUM(C7:M7) -> 892 | O7: 902 | P7: 1052 | Q7: =O7/P7 -> 0.85741445
A8: 14800532 | B8: Sannaplan | C8: 421 | D8: 235 | E8: 68 | F8: 71 | G8: 77 | H8: 34 | I8: 31 | J8: 27 | K8: 23 | L8: 6 | M8: 18 | N8: =SUM(C8:M8) -> 1011 | O8: 1023 | P8: 1237 | Q8: =O8/P8 -> 0.82700081
A9: 14800533 | B9: Sandarne | C9: 397 | D9: 296 | E9: 89 | F9: 127 | G9: 89 | H9: 51 | I9: 38 | J9: 39 | K9: 24 | L9: 6 | M9: 16 | N9: =SUM(C9:M9) -> 1172 | O9: 1187 | P9: 1457 | Q9: =O9/P9 -> 0.81468771
A10: 14800534 | B10: Klippan | C10: 273 | D10: 218 | E10: 57 | F10: 80 | G10: 81 | H10: 39 | I10: 29 | J10: 36 | K10: 19 | L10: 9 | M10: 11 | N10: =SUM(C10:M10) -> 852 | O10: 861 | P10: 1052 | Q10: =O10/P10 -> 0.81844106
A11: 14800535 | B11: Gröna Vallen | C11: 303 | D11: 209 | E11: 62 | F11: 55 | G11: 71 | H11: 23 | I11: 19 | J11: 16 | K11: 13 | L11: 6 | M11: 17 | N11: =SUM(C11:M11) -> 794 | O11: 808 | P11: 997 | Q11: =O11/P11 -> 0.81043129
A12: 14800536 | B12: Kusttorget | C12: 302 | D12: 255 | E12: 53 | F12: 83 | G12: 86 | H12: 43 | I12: 26 | J12: 21 | K12: 16 | L12: 4 | M12: 21 | N12: =SUM(C12:M12) -> 910 | O12: 923 | P12: 1193 | Q12: =O12/P12 -> 0.7736798
A13: 14800537 | B13: Chapmans Torg | C13: 221 | D13: 238 | E13: 55 | F13: 97 | G13: 76 | H13: 33 | I13: 21 | J13: 43 | K13: 26 | L13: 11 | M13: 17 | N13: =SUM(C13:M13) -> 838 | O13: 844 | P13: 1081 | Q13: =O13/P13 -> 0.78075856
... A24: 14800548 | B24: Gatenhielmska | C24: 370 | D24: 254 | E24: 79 | F24: 59 | G24: 78 | H24: 33 | I24: 33 | J24: 25 | K24: 25 | L24: 4 | M24: 17 | N24: =SUM(C24:M24) -> 977 | O24: 989 | P24: 1227 | Q24: =O24/P24 -> 0.80603097
B25: Majorna totalt | C25: =SUM(C2:C24) -> 7723 | D25: =SUM(D2:D24) -> 5519 | E25: =SUM(E2:E24) -> 1766 | F25: =SUM(F2:F24) -> 1753 | G25: =SUM(G2:G24) -> 1610 | H25: =SUM(H2:H24) -> 809 | I25: =SUM(I2:I24) -> 680 | J25: =SUM(J2:J24) -> 635 | ... P25: =SUM(P2:P24) -> 26737 | Q25: =O25/P25 -> 0.81654636

Sheet KF
A1: Distriktskod | B1: Valdistrikt | C1: V | D1: S | E1: MP | F1: M | G1: SD | H1: L | I1: D | J1: C | K1: KD | L1: FI | M1: K | N1: Övriga | O1: Giltiga röster | P1: Röstande | Q1: Röstberättigade | R1: Valdeltagande
A2: 14800526 | B2: Svalebo | C2: 240 | D2: 204 | E2: 74 | F2: 59 | G2: 72 | H2: 49 | I2: 23 | J2: 24 | K2: 27 | L2: 12 | M2: 10 | N2: 16 | O2: =SUM(C2:N2) -> 810 | P2: 825 | Q2: 1130 | R2: =P2/Q2 -> 0.7300885
A3: 14800527 | B3: Skytteskogen | C3: 252 | D3: 198 | E3: 152 | F3: 113 | G3: 39 | H3: 75 | I3: 74 | J3: 43 | K3: 27 | L3: 14 | M3: 4 | N3: 11 | O3: =SUM(C3:N3) -> 1002 | P3: 1007 | Q3: 1148 | R3: =P3/Q3 -> 0.8771777
A4: 14800528 | B4: Kungsladugård Östra | C4: 343 | D4: 196 | E4: 86 | F4: 57 | G4: 76 | H4: 23 | I4: 32 | J4: 30 | K4: 25 | L4: 12 | M4: 6 | N4: 22 | O4: =SUM(C4:N4) -> 908 | P4: 915 | Q4: 1135 | R4: =P4/Q4 -> 0.8061674
A5: 14800529 | B5: Kungsladugård Västra | C5: 353 | D5: 207 | E5: 104 | F5: 58 | G5: 60 | H5: 23 | I5: 32 | J5: 21 | K5: 13 | L5: 10 | M5: 12 | N5: 9 | O5: =SUM(C5:N5) -> 902 | P5: 913 | Q5: 1115 | R5: =P5/Q5 -> 0.81883408
A6: 14800530 | B6: Mariaplan | C6: 361 | D6: 164 | E6: 89 | F6: 43 | G6: 59 | H6: 26 | I6: 39 | J6: 12 | K6: 12 | L6: 18 | M6: 12 | N6: 7 | O6: =SUM(C6:N6) -> 842 | P6: 850 | Q6: 1034 | R6: =P6/Q6 -> 0.82205029
A7: 14800531 | B7: Silverkällan | C7: 325 | D7: 220 | E7: 90 | F7: 67 | G7: 48 | H7: 36 | I7: 31 | J7: 22 | K7: 14 | L7: 14 | M7: 7 | N7: 11 | O7: =SUM(C7:N7) -> 885 | P7: 897 | Q7: 1052 | R7: =P7/Q7 -> 0.8526616
A8: 14800532 | B8: Sannaplan | C8: 402 | D8: 210 | E8: 82 | F8: 64 | G8: 74 | H8: 47 | I8: 33 | J8: 29 | K8: 25 | L8: 23 | M8: 7 | N8: 15 | O8: =SUM(C8:N8) -> 1011 | P8: 1020 | Q8: 1237 | R8: =P8/Q8 -> 0.82457559
A9: 14800533 | B9: Sandarne | C9: 386 | D9: 264 | E9: 111 | F9: 143 | G9: 79 | H9: 39 | I9: 30 | J9: 32 | K9: 30 | L9: 30 | M9: 11 | N9: 18 | O9: =SUM(C9:N9) -> 1173 | P9: 1190 | Q9: 1457 | R9: =P9/Q9 -> 0.81674674
A10: 14800534 | B10: Klippan | C10: 259 | D10: 194 | E10: 68 | F10: 86 | G10: 87 | H10: 39 | I10: 36 | J10: 23 | K10: 31 | L10: 14 | M10: 10 | N10: 10 | O10: =SUM(C10:N10) -> 857 | P10: 864 | Q10: 1052 | R10: =P10/Q10 -> 0.82129278
A11: 14800535 | B11: Gröna Vallen | C11: 302 | D11: 180 | E11: 72 | F11: 57 | G11: 75 | H11: 22 | I11: 22 | J11: 21 | K11: 14 | L11: 18 | M11: 7 | N11: 14 | O11: =SUM(C11:N11) -> 804 | P11: 813 | Q11: 997 | R11: =P11/Q11 -> 0.81544634
A12: 14800536 | B12: Kusttorget | C12: 305 | D12: 235 | E12: 56 | F12: 83 | G12: 87 | H12: 44 | I12: 27 | J12: 20 | K12: 14 | L12: 13 | M12: 11 | N12: 22 | O12: =SUM(C12:N12) -> 917 | P12: 927 | Q12: 1193 | R12: =P12/Q12 -> 0.77703269
A13: 14800537 | B13: Chapmans Torg | C13: 227 | D13: 209 | E13: 66 | F13: 104 | G13: 80 | H13: 35 | I13: 35 | J13: 21 | K13: 22 | L13: 14 | M13: 10 | N13: 14 | O13: =SUM(C13:N13) -> 837 | P13: 843 | Q13: 1081 | R13: =P13/Q13 -> 0.77983349
... A24: 14800548 | B24: Gatenhielmska | C24: 360 | D24: 240 | E24: 93 | F24: 54 | G24: 75 | H24: 36 | I24: 28 | J24: 25 | K24: 22 | L24: 14 | M24: 15 | N24: 16 | O24: =SUM(C24:N24) -> 978 | P24: 988 | Q24: 1227 | R24: =P24/Q24 -> 0.80521597
B25: Majorna totalt | C25: =SUM(C2:C24) -> 7479 | D25: =SUM(D2:D24) -> 4997 | E25: =SUM(E2:E24) -> 2067 | F25: =SUM(F2:F24) -> 1783 | G25: =SUM(G2:G24) -> 1578 | H25: =SUM(H2:H24) -> 848 | I25: =SUM(I2:I24) -> 844 | J25: =SUM(J2:J24) -> 627 | ... Q25: =SUM(Q2:Q24) -> 26737 | R25: =P25/Q25 -> 0.8177806

Sheet Metod & källor
A1: Metod och källor
A3: Avgränsning: "Klassiska Majorna" = primärområdena 101 Kungsladugård, 102 Sanna, 103 Majorna, 104 Stigberget (Göteborgs Stads områdesindelning).
A4: Valdistrikt identifierade genom GIS-överlagring: Valmyndighetens valdistriktspolygoner (valgeografi 2022, SWEREF99 TM) mot Göteborgs Stads primärområdesgränser (stadens ArcGIS-tjänst GTB_adm_primäromraden).
A5: Resultat: exakt 23 valdistrikt (14800526–14800548, valkrets Västra Centrum). 22 av 23 ligger till 100,0 % inom området; Söderlingska Ängen (14800545) till 98,4 %. Tillsammans täcker de 100,00 % av områdets yta.
A6: Distriktens NAMN är inte tillförlitliga för områdestillhörighet: t.ex. ligger valdistriktet "Stigberget" (14800503) i primärområde Masthugget, inte i Stigberget.
A8: Röstdata: Valmyndighetens slutliga rösträkning per valdistrikt, riksdags-, region- och kommunvalet 2022 (rådatafiler från val.se, "Röster per distrikt - slutligt antal röster inklusive totalt valdeltagande").
A9: Andel = parti / summa giltiga röster. Valdeltagande = röstande / röstberättigade.
A10: Jämförelsetal Göteborg inkluderar uppsamlingsdistriktet (som saknar geografi och därför inte kan fördelas på stadsdelar). Majornas siffror omfattar de 23 geografiska distrikten.
A11: Röstberättigade skiljer sig mellan riksdagsval (endast svenska medborgare) och region-/kommunval.
A13: Verifiering: distriktssiffror stickprovskontrollerade mot SVT:s publicerade valresultat (identiska), rikets och Göteborgs procentsatser kontrollerade mot officiellt slutresultat (identiska: t.ex. riket S 30,33 %, valdeltagande 84,21 %; Göteborg valdeltagande 80,71 %).
A15: Källor:
A16: https://www.val.se/valresultat-och-statistik/statistik-och-data/radata-fran-val-2002-2022
... A19: Sammanställd 2026-09-02.
